Workbook

Sheet Top Targets
A1: Wholesale non-QM prospects: banks and credit unions headquartered in LA, Orange, Riverside and San Bernardino counties
A2: Data as of June 30, 2026 (FDIC/NCUA call reports) and calendar 2025 (HMDA). Tier 1 and Tier 2 only, sorted by capacity score. Scores and tiers pull live from the Banks / Credit Unions tabs.
A4: Rank | B4: Type | C4: Institution | D4: City | E4: County | F4: Total assets ($M) | G4: Loan-to-deposit / share | H4: Liquidity | I4: Capital ratio | J4: % kept in portfolio (HMDA) | K4: Wholesale status | L4: Capacity score | M4: Tier | N4: Why they might say yes
A5: 1 | B5: Credit Union | C5: ='Credit Unions'!B40 | D5: ='Credit Unions'!C40 | E5: ='Credit Unions'!D40 | F5: ='Credit Unions'!E40 | G5: ='Credit Unions'!I40 | H5: ='Credit Unions'!J40 | I5: ='Credit Unions'!K40 | J5: =IF('Credit Unions'!U40="","n/a",'Credit Unions'!U40) | K5: ='Credit Unions'!Y40 | L5: ='Credit Unions'!Z40 | M5: ='Credit Unions'!AA40 | N5: Lends out only 35% of deposits; 69% of assets in cash/securities; strong capital (13.1%); little or no mortgage lending today, so you'd be pitching a new business line
A6: 2 | B6: Credit Union | C6: ='Credit Unions'!B39 | D6: ='Credit Unions'!C39 | E6: ='Credit Unions'!D39 | F6: ='Credit Unions'!E39 | G6: ='Credit Unions'!I39 | H6: ='Credit Unions'!J39 | I6: ='Credit Unions'!K39 | J6: =IF('Credit Unions'!U39="","n/a",'Credit Unions'!U39) | K6: ='Credit Unions'!Y39 | L6: ='Credit Unions'!Z39 | M6: ='Credit Unions'!AA39 | N6: Lends out only 47% of deposits; 61% of assets in cash/securities; little or no mortgage lending today, so you'd be pitching a new business line
A7: 3 | B7: Bank | C7: ='Banks'!B4 | D7: ='Banks'!C4 | E7: ='Banks'!D4 | F7: ='Banks'!F4 | G7: ='Banks'!J4 | H7: ='Banks'!K4 | I7: ='Banks'!L4 | J7: =IF('Banks'!T4="","n/a",'Banks'!T4) | K7: ='Banks'!X4 | L7: ='Banks'!Y4 | M7: ='Banks'!Z4 | N7: Lends out only 48% of deposits; 55% of assets in cash/securities; deposits outgrowing loans; little or no mortgage lending today, so you'd be pitching a new business line
A8: 4 | B8: Bank | C8: ='Banks'!B8 | D8: ='Banks'!C8 | E8: ='Banks'!D8 | F8: ='Banks'!F8 | G8: ='Banks'!J8 | H8: ='Banks'!K8 | I8: ='Banks'!L8 | J8: =IF('Banks'!T8="","n/a",'Banks'!T8) | K8: ='Banks'!X8 | L8: ='Banks'!Y8 | M8: ='Banks'!Z8 | N8: CRE at 470% of capital (above the 300% regulatory guide) so resi would diversify; deposits outgrowing loans; little or no mortgage lending today, so you'd be pitching a new business line
A9: 5 | B9: Bank | C9: ='Banks'!B34 | D9: ='Banks'!C34 | E9: ='Banks'!D34 | F9: ='Banks'!F34 | G9: ='Banks'!J34 | H9: ='Banks'!K34 | I9: ='Banks'!L34 | J9: =IF('Banks'!T34="","n/a",'Banks'!T34) | K9: ='Banks'!X34 | L9: ='Banks'!Y34 | M9: ='Banks'!Z34 | N9: CRE at 347% of capital (above the 300% regulatory guide) so resi would diversify; deposits outgrowing loans; strong capital (17.8%); little or no mortgage lending today, so you'd be pitching a new business line
A10: 6 | B10: Bank | C10: ='Banks'!B24 | D10: ='Banks'!C24 | E10: ='Banks'!D24 | F10: ='Banks'!F24 | G10: ='Banks'!J24 | H10: ='Banks'!K24 | I10: ='Banks'!L24 | J10: =IF('Banks'!T24="","n/a",'Banks'!T24) | K10: ='Banks'!X24 | L10: ='Banks'!Y24 | M10: ='Banks'!Z24 | N10: Strong capital (15.9%); little or no mortgage lending today, so you'd be pitching a new business line
A11: 7 | B11: Credit Union | C11: ='Credit Unions'!B19 | D11: ='Credit Unions'!C19 | E11: ='Credit Unions'!D19 | F11: ='Credit Unions'!E19 | G11: ='Credit Unions'!I19 | H11: ='Credit Unions'!J19 | I11: ='Credit Unions'!K19 | J11: =IF('Credit Unions'!U19="","n/a",'Credit Unions'!U19) | K11: ='Credit Unions'!Y19 | L11: ='Credit Unions'!Z19 | M11: ='Credit Unions'!AA19 | N11: Lends out only 56% of deposits; 45% of assets in cash/securities; keeps 100% of its mortgages (portfolio lender)
A12: 8 | B12: Bank | C12: ='Banks'!B27 | D12: ='Banks'!C27 | E12: ='Banks'!D27 | F12: ='Banks'!F27 | G12: ='Banks'!J27 | H12: ='Banks'!K27 | I12: ='Banks'!L27 | J12: =IF('Banks'!T27="","n/a",'Banks'!T27) | K12: ='Banks'!X27 | L12: ='Banks'!Y27 | M12: ='Banks'!Z27 | N12: Lends out only 60% of deposits; 50% of assets in cash/securities; strong capital (12.5%); little or no mortgage lending today, so you'd be pitching a new business line
A13: 9 | B13: Credit Union | C13: ='Credit Unions'!B15 | D13: ='Credit Unions'!C15 | E13: ='Credit Unions'!D15 | F13: ='Credit Unions'!E15 | G13: ='Credit Unions'!I15 | H13: ='Credit Unions'!J15 | I13: ='Credit Unions'!K15 | J13: =IF('Credit Unions'!U15="","n/a",'Credit Unions'!U15) | K13: ='Credit Unions'!Y15 | L13: ='Credit Unions'!Z15 | M13: ='Credit Unions'!AA15 | N13: Lends out only 62% of deposits; 42% of assets in cash/securities; strong capital (13.1%); keeps 93% of its mortgages (portfolio lender)
A14: 10 | B14: Credit Union | C14: ='Credit Unions'!B21 | D14: ='Credit Unions'!C21 | E14: ='Credit Unions'!D21 | F14: ='Credit Unions'!E21 | G14: ='Credit Unions'!I21 | H14: ='Credit Unions'!J21 | I14: ='Credit Unions'!K21 | J14: =IF('Credit Unions'!U21="","n/a",'Credit Unions'!U21) | K14: ='Credit Unions'!Y21 | L14: ='Credit Unions'!Z21 | M14: ='Credit Unions'!AA21 | N14: Lends out only 61% of deposits; 42% of assets in cash/securities; keeps 93% of its mortgages (portfolio lender)
A15: 11 | B15: Credit Union | C15: ='Credit Unions'!B35 | D15: ='Credit Unions'!C35 | E15: ='Credit Unions'!D35 | F15: ='Credit Unions'!E35 | G15: ='Credit Unions'!I35 | H15: ='Credit Unions'!J35 | I15: ='Credit Unions'!K35 | J15: =IF('Credit Unions'!U35="","n/a",'Credit Unions'!U35) | K15: ='Credit Unions'!Y35 | L15: ='Credit Unions'!Z35 | M15: ='Credit Unions'!AA35 | N15: Lends out only 55% of deposits; 34% of assets in cash/securities; keeps 100% of its mortgages (portfolio lender)
A16: 12 | B16: Bank | C16: ='Banks'!B16 | D16: ='Banks'!C16 | E16: ='Banks'!D16 | F16: ='Banks'!F16 | G16: ='Banks'!J16 | H16: ='Banks'!K16 | I16: ='Banks'!L16 | J16: =IF('Banks'!T16="","n/a",'Banks'!T16) | K16: ='Banks'!X16 | L16: ='Banks'!Y16 | M16: ='Banks'!Z16 | N16: Lends out only 74% of deposits; 33% of assets in cash/securities; deposits outgrowing loans; little or no mortgage lending today, so you'd be pitching a new business line
A17: 13 | B17: Credit Union | C17: ='Credit Unions'!B9 | D17: ='Credit Unions'!C9 | E17: ='Credit Unions'!D9 | F17: ='Credit Unions'!E9 | G17: ='Credit Unions'!I9 | H17: ='Credit Unions'!J9 | I17: ='Credit Unions'!K9 | J17: =IF('Credit Unions'!U9="","n/a",'Credit Unions'!U9) | K17: ='Credit Unions'!Y9 | L17: ='Credit Unions'!Z9 | M17: ='Credit Unions'!AA9 | N17: Lends out only 60% of deposits; 58% of assets in cash/securities; strong capital (12.6%); keeps 100% of its mortgages (portfolio lender); already made 8 IO/balloon/non-amortizing loans
A18: 14 | B18: Credit Union | C18: ='Credit Unions'!B45 | D18: ='Credit Unions'!C45 | E18: ='Credit Unions'!D45 | F18: ='Credit Unions'!E45 | G18: ='Credit Unions'!I45 | H18: ='Credit Unions'!J45 | I18: ='Credit Unions'!K45 | J18: =IF('Credit Unions'!U45="","n/a",'Credit Unions'!U45) | K18: ='Credit Unions'!Y45 | L18: ='Credit Unions'!Z45 | M18: ='Credit Unions'!AA45 | N18: Lends out only 57% of deposits; 45% of assets in cash/securities; strong capital (13.1%); little or no mortgage lending today, so you'd be pitching a new business line
A19: 15 | B19: Bank | C19: ='Banks'!B5 | D19: ='Banks'!C5 | E19: ='Banks'!D5 | F19: ='Banks'!F5 | G19: ='Banks'!J5 | H19: ='Banks'!K5 | I19: ='Banks'!L5 | J19: =IF('Banks'!T5="","n/a",'Banks'!T5) | K19: ='Banks'!X5 | L19: ='Banks'!Y5 | M19: ='Banks'!Z5 | N19: Deposits outgrowing loans; strong capital (14.7%); keeps 100% of its mortgages (portfolio lender); already made 2 IO/balloon/non-amortizing loans
A20: 16 | B20: Credit Union | C20: ='Credit Unions'!B42 | D20: ='Credit Unions'!C42 | E20: ='Credit Unions'!D42 | F20: ='Credit Unions'!E42 | G20: ='Credit Unions'!I42 | H20: ='Credit Unions'!J42 | I20: ='Credit Unions'!K42 | J20: =IF('Credit Unions'!U42="","n/a",'Credit Unions'!U42) | K20: ='Credit Unions'!Y42 | L20: ='Credit Unions'!Z42 | M20: ='Credit Unions'!AA42 | N20: Lends out only 69% of deposits; 36% of assets in cash/securities; keeps 100% of its mortgages (portfolio lender)
A21: 17 | B21: Bank | C21: ='Banks'!B11 | D21: ='Banks'!C11 | E21: ='Banks'!D11 | F21: ='Banks'!F11 | G21: ='Banks'!J11 | H21: ='Banks'!K11 | I21: ='Banks'!L11 | J21: =IF('Banks'!T11="","n/a",'Banks'!T11) | K21: ='Banks'!X11 | L21: ='Banks'!Y11 | M21: ='Banks'!Z11 | N21: Strong capital (13.9%); little or no mortgage lending today, so you'd be pitching a new business line
A22: 18 | B22: Bank | C22: ='Banks'!B20 | D22: ='Banks'!C20 | E22: ='Banks'!D20 | F22: ='Banks'!F20 | G22: ='Banks'!J20 | H22: ='Banks'!K20 | I22: ='Banks'!L20 | J22: =IF('Banks'!T20="","n/a",'Banks'!T20) | K22: ='Banks'!X20 | L22: ='Banks'!Y20 | M22: ='Banks'!Z20 | N22: CRE at 611% of capital (above the 300% regulatory guide) so resi would diversify; little or no mortgage lending today, so you'd be pitching a new business line
A23: 19 | B23: Credit Union | C23: ='Credit Unions'!B46 | D23: ='Credit Unions'!C46 | E23: ='Credit Unions'!D46 | F23: ='Credit Unions'!E46 | G23: ='Credit Unions'!I46 | H23: ='Credit Unions'!J46 | I23: ='Credit Unions'!K46 | J23: =IF('Credit Unions'!U46="","n/a",'Credit Unions'!U46) | K23: ='Credit Unions'!Y46 | L23: ='Credit Unions'!Z46 | M23: ='Credit Unions'!AA46 | N23: Lends out only 65% of deposits; 39% of assets in cash/securities; deposits outgrowing loans
A24: 20 | B24: Credit Union | C24: ='Credit Unions'!B6 | D24: ='Credit Unions'!C6 | E24: ='Credit Unions'!D6 | F24: ='Credit Unions'!E6 | G24: ='Credit Unions'!I6 | H24: ='Credit Unions'!J6 | I24: ='Credit Unions'!K6 | J24: =IF('Credit Unions'!U6="","n/a",'Credit Unions'!U6) | K24: ='Credit Unions'!Y6 | L24: ='Credit Unions'!Z6 | M24: ='Credit Unions'!AA6 | N24: Lends out only 70% of deposits; 43% of assets in cash/securities; keeps 100% of its mortgages (portfolio lender); already made 97 IO/balloon/non-amortizing loans
A25: 21 | B25: Credit Union | C25: ='Credit Unions'!B30 | D25: ='Credit Unions'!C30 | E25: ='Credit Unions'!D30 | F25: ='Credit Unions'!E30 | G25: ='Credit Unions'!I30 | H25: ='Credit Unions'!J30 | I25: ='Credit Unions'!K30 | J25: =IF('Credit Unions'!U30="","n/a",'Credit Unions'!U30) | K25: ='Credit Unions'!Y30 | L25: ='Credit Unions'!Z30 | M25: ='Credit Unions'!AA30 | N25: Lends out only 57% of deposits; 45% of assets in cash/securities; strong capital (13.5%); keeps 100% of its mortgages (portfolio lender)
A26: 22 | B26: Credit Union | C26: ='Credit Unions'!B63 | D26: ='Credit Unions'!C63 | E26: ='Credit Unions'!D63 | F26: ='Credit Unions'!E63 | G26: ='Credit Unions'!I63 | H26: ='Credit Unions'!J63 | I26: ='Credit Unions'!K63 | J26: =IF('Credit Unions'!U63="","n/a",'Credit Unions'!U63) | K26: ='Credit Unions'!Y63 | L26: ='Credit Unions'!Z63 | M26: ='Credit Unions'!AA63 | N26: Lends out only 50% of deposits; 53% of assets in cash/securities; deposits outgrowing loans; strong capital (23.4%); little or no mortgage lending today, so you'd be pitching a new business line
A27: 23 | B27: Credit Union | C27: ='Credit Unions'!B52 | D27: ='Credit Unions'!C52 | E27: ='Credit Unions'!D52 | F27: ='Credit Unions'!E52 | G27: ='Credit Unions'!I52 | H27: ='Credit Unions'!J52 | I27: ='Credit Unions'!K52 | J27: =IF('Credit Unions'!U52="","n/a",'Credit Unions'!U52) | K27: ='Credit Unions'!Y52 | L27: ='Credit Unions'!Z52 | M27: ='Credit Unions'!AA52 | N27: Lends out only 54% of deposits; 48% of assets in cash/securities; strong capital (14.0%); already made 1 IO/balloon/non-amortizing loans
A28: 24 | B28: Credit Union | C28: ='Credit Unions'!B59 | D28: ='Credit Unions'!C59 | E28: ='Credit Unions'!D59 | F28: ='Credit Unions'!E59 | G28: ='Credit Unions'!I59 | H28: ='Credit Unions'!J59 | I28: ='Credit Unions'!K59 | J28: =IF('Credit Unions'!U59="","n/a",'Credit Unions'!U59) | K28: ='Credit Unions'!Y59 | L28: ='Credit Unions'!Z59 | M28: ='Credit Unions'!AA59 | N28: Lends out only 46% of deposits; 52% of assets in cash/securities; little or no mortgage lending today, so you'd be pitching a new business line
A29: 25 | B29: Credit Union | C29: ='Credit Unions'!B11 | D29: ='Credit Unions'!C11 | E29: ='Credit Unions'!D11 | F29: ='Credit Unions'!E11 | G29: ='Credit Unions'!I11 | H29: ='Credit Unions'!J11 | I29: ='Credit Unions'!K11 | J29: =IF('Credit Unions'!U11="","n/a",'Credit Unions'!U11) | K29: ='Credit Unions'!Y11 | L29: ='Credit Unions'!Z11 | M29: ='Credit Unions'!AA11 | N29: Lends out only 60% of deposits; 46% of assets in cash/securities; deposits outgrowing loans; already made 1 IO/balloon/non-amortizing loans
A30: 26 | B30: Credit Union | C30: ='Credit Unions'!B54 | D30: ='Credit Unions'!C54 | E30: ='Credit Unions'!D54 | F30: ='Credit Unions'!E54 | G30: ='Credit Unions'!I54 | H30: ='Credit Unions'!J54 | I30: ='Credit Unions'!K54 | J30: =IF('Credit Unions'!U54="","n/a",'Credit Unions'!U54) | K30: ='Credit Unions'!Y54 | L30: ='Credit Unions'!Z54 | M30: ='Credit Unions'!AA54 | N30: Lends out only 55% of deposits; 49% of assets in cash/securities; little or no mortgage lending today, so you'd be pitching a new business line
A31: 27 | B31: Credit Union | C31: ='Credit Unions'!B62 | D31: ='Credit Unions'!C62 | E31: ='Credit Unions'!D62 | F31: ='Credit Unions'!E62 | G31: ='Credit Unions'!I62 | H31: ='Credit Unions'!J62 | I31: ='Credit Unions'!K62 | J31: =IF('Credit Unions'!U62="","n/a",'Credit Unions'!U62) | K31: ='Credit Unions'!Y62 | L31: ='Credit Unions'!Z62 | M31: ='Credit Unions'!AA62 | N31: Lends out only 51% of deposits; 41% of assets in cash/securities; little or no mortgage lending today, so you'd be pitching a new business line
A32: 28 | B32: Bank | C32: ='Banks'!B45 | D32: ='Banks'!C45 | E32: ='Banks'!D45 | F32: ='Banks'!F45 | G32: ='Banks'!J45 | H32: ='Banks'!K45 | I32: ='Banks'!L45 | J32: =IF('Banks'!T45="","n/a",'Banks'!T45) | K32: ='Banks'!X45 | L32: ='Banks'!Y45 | M32: ='Banks'!Z45 | N32: Lends out only 79% of deposits; deposits outgrowing loans; strong capital (13.5%); little or no mortgage lending today, so you'd be pitching a new business line
A33: 29 | B33: Credit Union | C33: ='Credit Unions'!B58 | D33: ='Credit Unions'!C58 | E33: ='Credit Unions'!D58 | F33: ='Credit Unions'!E58 | G33: ='Credit Unions'!I58 | H33: ='Credit Unions'!J58 | I33: ='Credit Unions'!K58 | J33: =IF('Credit Unions'!U58="","n/a",'Credit Unions'!U58) | K33: ='Credit Unions'!Y58 | L33: ='Credit Unions'!Z58 | M33: ='Credit Unions'!AA58 | N33: 31% of assets in cash/securities; strong capital (23.4%); little or no mortgage lending today, so you'd be pitching a new business line
A34: 30 | B34: Credit Union | C34: ='Credit Unions'!B49 | D34: ='Credit Unions'!C49 | E34: ='Credit Unions'!D49 | F34: ='Credit Unions'!E49 | G34: ='Credit Unions'!I49 | H34: ='Credit Unions'!J49 | I34: ='Credit Unions'!K49 | J34: =IF('Credit Unions'!U49="","n/a",'Credit Unions'!U49) | K34: ='Credit Unions'!Y49 | L34: ='Credit Unions'!Z49 | M34: ='Credit Unions'!AA49 | N34: Lends out only 59% of deposits; 44% of assets in cash/securities; little or no mortgage lending today, so you'd be pitching a new business line
A35: 31 | B35: Credit Union | C35: ='Credit Unions'!B61 | D35: ='Credit Unions'!C61 | E35: ='Credit Unions'!D61 | F35: ='Credit Unions'!E61 | G35: ='Credit Unions'!I61 | H35: ='Credit Unions'!J61 | I35: ='Credit Unions'!K61 | J35: =IF('Credit Unions'!U61="","n/a",'Credit Unions'!U61) | K35: ='Credit Unions'!Y61 | L35: ='Credit Unions'!Z61 | M35: ='Credit Unions'!AA61 | N35: Lends out only 61% of deposits; 43% of assets in cash/securities; little or no mortgage lending today, so you'd be pitching a new business line
A36: 32 | B36: Credit Union | C36: ='Credit Unions'!B57 | D36: ='Credit Unions'!C57 | E36: ='Credit Unions'!D57 | F36: ='Credit Unions'!E57 | G36: ='Credit Unions'!I57 | H36: ='Credit Unions'!J57 | I36: ='Credit Unions'!K57 | J36: =IF('Credit Unions'!U57="","n/a",'Credit Unions'!U57) | K36: ='Credit Unions'!Y57 | L36: ='Credit Unions'!Z57 | M36: ='Credit Unions'!AA57 | N36: Lends out only 59% of deposits; 46% of assets in cash/securities; strong capital (13.8%); little or no mortgage lending today, so you'd be pitching a new business line
A37: 33 | B37: Bank | C37: ='Banks'!B42 | D37: ='Banks'!C42 | E37: ='Banks'!D42 | F37: ='Banks'!F42 | G37: ='Banks'!J42 | H37: ='Banks'!K42 | I37: ='Banks'!L42 | J37: =IF('Banks'!T42="","n/a",'Banks'!T42) | K37: ='Banks'!X42 | L37: ='Banks'!Y42 | M37: ='Banks'!Z42 | N37: Lends out only 69% of deposits; 41% of assets in cash/securities; strong capital (16.4%)
A38: 34 | B38: Credit Union | C38: ='Credit Unions'!B48 | D38: ='Credit Unions'!C48 | E38: ='Credit Unions'!D48 | F38: ='Credit Unions'!E48 | G38: ='Credit Unions'!I48 | H38: ='Credit Unions'!J48 | I38: ='Credit Unions'!K48 | J38: =IF('Credit Unions'!U48="","n/a",'Credit Unions'!U48) | K38: ='Credit Unions'!Y48 | L38: ='Credit Unions'!Z48 | M38: ='Credit Unions'!AA48 | N38: Lends out only 52% of deposits; 45% of assets in cash/securities; strong capital (13.9%)
A39: 35 | B39: Credit Union | C39: ='Credit Unions'!B65 | D39: ='Credit Unions'!C65 | E39: ='Credit Unions'!D65 | F39: ='Credit Unions'!E65 | G39: ='Credit Unions'!I65 | H39: ='Credit Unions'!J65 | I39: ='Credit Unions'!K65 | J39: =IF('Credit Unions'!U65="","n/a",'Credit Unions'!U65) | K39: ='Credit Unions'!Y65 | L39: ='Credit Unions'!Z65 | M39: ='Credit Unions'!AA65 | N39: Lends out only 71% of deposits; 34% of assets in cash/securities; strong capital (13.5%); little or no mortgage lending today, so you'd be pitching a new business line
A40: 36 | B40: Bank | C40: ='Banks'!B46 | D40: ='Banks'!C46 | E40: ='Banks'!D46 | F40: ='Banks'!F46 | G40: ='Banks'!J46 | H40: ='Banks'!K46 | I40: ='Banks'!L46 | J40: =IF('Banks'!T46="","n/a",'Banks'!T46) | K40: ='Banks'!X46 | L40: ='Banks'!Y46 | M40: ='Banks'!Z46 | N40: Lends out only 76% of deposits; deposits outgrowing loans; little or no mortgage lending today, so you'd be pitching a new business line
A41: 37 | B41: Bank | C41: ='Banks'!B6 | D41: ='Banks'!C6 | E41: ='Banks'!D6 | F41: ='Banks'!F6 | G41: ='Banks'!J6 | H41: ='Banks'!K6 | I41: ='Banks'!L6 | J41: =IF('Banks'!T6="","n/a",'Banks'!T6) | K41: ='Banks'!X6 | L41: ='Banks'!Y6 | M41: ='Banks'!Z6 | N41: Lends out only 79% of deposits; little or no mortgage lending today, so you'd be pitching a new business line
...

Sheet Read Me
A1: How to use this workbook
A2: Top Targets: the short list. Tier 1 = strongest balance-sheet capacity and NOT already taking broker loans. Start there.
A3: Banks / Credit Unions: full detail on every institution in scope. Filter by County, Tier or Wholesale status. Fill in the yellow CEO / contact and Notes columns as you research.
A4: Scoring: the weights behind the capacity score. Change the blue numbers to re-rank everything.
A6: What the columns mean
A7: Loan-to-deposit (banks) / Loan-to-share (CUs): total loans divided by deposits. Under ~80% means deposits are sitting idle and earning less than a loan would.
A8: Liquidity: cash plus investment securities as a share of assets. A high number = money available to redeploy into loans.
A9: Capital ratio: Tier 1 leverage ratio (banks) or net worth ratio (CUs). 10%+ is comfortable; portfolio non-QM uses capital, so they need room.
A10: CRE concentration: non-owner-occupied CRE + multifamily + construction loans divided by total risk-based capital. Regulators scrutinize banks above 300%; 1-4 family loans help them diversify.
A11: % kept in portfolio: share of 2025 HMDA originations NOT sold the same year. High = they already hold mortgages on their books, which non-QM requires (or they sell to a non-QM investor).
A12: Non-QM-feature loans: 2025 originations with interest-only, balloon, negative-amortization or other non-amortizing terms. These loans cannot be QM, so a count above zero means they already do some non-QM.
A13: Broker-channel share: share of 2025 applications NOT submitted directly to the institution (HMDA "submission of application" = 2). This is the best public signal of an existing wholesale/broker channel.
... A83: Los Angeles Lee CU (Credit Union, $1M): Under $100M in assets (too small to fund a wholesale channel)

Sheet Scoring
A1: Capacity score settings (edit the blue numbers; every score recalculates)
A3: Bank weights | C3: Total | D3: =SUM(B4:B9)
A4: Low loan-to-deposit ratio | B4: 0.3
A5: High liquidity (cash + securities / assets) | B5: 0.2
A6: Strong capital (leverage ratio) | B6: 0.15
A7: Deposits growing faster than loans | B7: 0.1
A8: High CRE concentration (needs to diversify) | B8: 0.15
A9: Low 1-4 family share of loans (room to add) | B9: 0.1
A10: Credit union weights | C10: Total | D10: =SUM(B11:B16)
A11: Low loan-to-share ratio | B11: 0.3
A12: High liquidity (cash + investments / assets) | B12: 0.2
A13: Strong net worth ratio | B13: 0.15
A14: Shares growing faster than loans | B14: 0.1
A15: Low mortgage originations vs. assets | B15: 0.15
A16: Low 1st-mortgage share of loans (room to add) | B16: 0.1
A17: Tier cutoffs
A18: Tier 1 minimum score | B18: 60
A19: Tier 2 minimum score | B19: 45
A20: Tier 1 minimum total assets ($M) | B20: 300
A22: How the score works
A23: Each institution is ranked against its peers on each factor (0% = worst in group, 100% = best), banks against banks, credit unions against credit unions.
A24: The score is the weighted average of those ranks, times 100. Higher means more balance-sheet room to add mortgages.
A25: Tier 1 = score at or above the Tier 1 cutoff AND assets at or above the Tier 1 size floor AND not already taking broker loans. The size floor exists because a very small institution rarely has the staff or balance sheet to support a wholesale channel. Tier 2 = score at or above the Tier 2 cutoff. Everything else is Tier 3.
A26: A blank input (e.g., missing prior-year data after a merger) is treated as middle-of-the-pack (50%).

Sheet Banks
A1: Key | B1: Institution | C1: City | D1: County | E1: Website | F1: Total assets ($M) | G1: Deposits ($M) | H1: Total loans ($M) | I1: 1-4 family resi loans ($M) | J1: Loan-to-deposit | K1: Liquidity (cash+sec / assets) | L1: Leverage capital ratio | M1: Resi % of loans | N1: CRE concentration (% of capital) | O1: Deposit growth YoY | P1: Loan growth YoY | Q1: Funding gap (dep g - loan g) | R1: HMDA 2025 originations (#) | S1: HMDA 2025 volume ($M) | T1: % kept in portfolio | U1: Non-QM-feature loans (IO/balloon/non-amort.) | V1: Investor / business-purpose loans | W1: Broker-channel share | X1: Wholesale status | Y1: Capacity score | Z1: Tier | AA1: CEO / contact (fill in) | AB1: Notes (fill in)
A2: bank:24170 | B2: Hanmi Bank | C2: Los Angeles | D2: Los Angeles | E2: www.hanmi.com | F2: 7954.215 | G2: 6963.809 | H2: 6552.281 | I2: 1006.667 | J2: =IF(G2=0,"",H2/G2) | K2: 0.14852578 | L2: 0.11707843 | M2: =IF(H2=0,"",I2/H2) | N2: 3.1541174 | O2: 0.033505094 | P2: 0.030951448 | Q2: =IF(OR(O2="",P2=""),"",O2-P2) | R2: 73 | S2: 56.465 | T2: 0.94520548 | V2: 39 | X2: Unknown (small filer, channel not reported) | Y2: =ROUND(100*(Scoring!$B$4*(1-IFERROR(PERCENTRANK($J$2:$J$46,J2),0.5))+Scoring!$B$5*IFERROR(PERCENTRANK($K$2:$K$46,K2),0.5)+Scoring!$B$6*IFERROR(PERCENTRANK($L$2:$L$46,L2),0.5)+Scoring!$B$7*IFERROR(PERCENTRANK($Q$2:$Q$46,Q2),0.5)+Scoring!$B$8*IFERROR(PERCENTRANK($N$2:$N$46,N2),0.5)+Scoring!$B$9*(1-IFERROR(PERCENTRANK($M$2:$M$46,M2),0.5))),0) | Z2: =IF(AND(Y2>=Scoring!$B$18,F2>=Scoring!$B$20,X2<>"Already takes broker loans"),"Tier 1",IF(Y2>=Scoring!$B$19,"Tier 2","Tier 3"))
A3: bank:33539 | B3: Preferred Bank | C3: Los Angeles | D3: Los Angeles | E3: www.preferredbank.com | F3: 7731.004 | G3: 6476.766 | H3: 6279.342 | I3: 736.088 | J3: =IF(G3=0,"",H3/G3) | K3: 0.16741396 | L3: 0.10554007 | M3: =IF(H3=0,"",I3/H3) | N3: 3.5726449 | O3: 0.064644695 | P3: 0.092501989 | Q3: =IF(OR(O3="",P3=""),"",O3-P3) | R3: 166 | S3: 139.85 | T3: 1 | V3: 37 | X3: Unknown (small filer, channel not reported) | Y3: =ROUND(100*(Scoring!$B$4*(1-IFERROR(PERCENTRANK($J$2:$J$46,J3),0.5))+Scoring!$B$5*IFERROR(PERCENTRANK($K$2:$K$46,K3),0.5)+Scoring!$B$6*IFERROR(PERCENTRANK($L$2:$L$46,L3),0.5)+Scoring!$B$7*IFERROR(PERCENTRANK($Q$2:$Q$46,Q3),0.5)+Scoring!$B$8*IFERROR(PERCENTRANK($N$2:$N$46,N3),0.5)+Scoring!$B$9*(1-IFERROR(PERCENTRANK($M$2:$M$46,M3),0.5))),0) | Z3: =IF(AND(Y3>=Scoring!$B$18,F3>=Scoring!$B$20,X3<>"Already takes broker loans"),"Tier 1",IF(Y3>=Scoring!$B$19,"Tier 2","Tier 3"))
A4: bank:18618 | B4: SMBC MANUBANK | C4: Los Angeles | D4: Los Angeles | E4: www.smbcmanubank.com | F4: 6596.628 | G4: 5564.446 | H4: 2683.716 | I4: 5.187 | J4: =IF(G4=0,"",H4/G4) | K4: 0.55362755 | L4: 0.096265967 | M4: =IF(H4=0,"",I4/H4) | N4: 1.5473777 | O4: -0.00081038485 | P4: -0.40229641 | Q4: =IF(OR(O4="",P4=""),"",O4-P4) | X4: No HMDA mortgage reporting | Y4: =ROUND(100*(Scoring!$B$4*(1-IFERROR(PERCENTRANK($J$2:$J$46,J4),0.5))+Scoring!$B$5*IFERROR(PERCENTRANK($K$2:$K$46,K4),0.5)+Scoring!$B$6*IFERROR(PERCENTRANK($L$2:$L$46,L4),0.5)+Scoring!$B$7*IFERROR(PERCENTRANK($Q$2:$Q$46,Q4),0.5)+Scoring!$B$8*IFERROR(PERCENTRANK($N$2:$N$46,N4),0.5)+Scoring!$B$9*(1-IFERROR(PERCENTRANK($M$2:$M$46,M4),0.5))),0) | Z4: =IF(AND(Y4>=Scoring!$B$18,F4>=Scoring!$B$20,X4<>"Already takes broker loans"),"Tier 1",IF(Y4>=Scoring!$B$19,"Tier 2","Tier 3"))
A5: bank:19416 | B5: CTBC Bank Corp. (USA) | C5: Los Angeles | D5: Los Angeles | E5: http://www.ctbcbankusa.com | F5: 5872.649 | G5: 5018.563 | H5: 4418.792 | I5: 1497.789 | J5: =IF(G5=0,"",H5/G5) | K5: 0.2135011 | L5: 0.14667221 | M5: =IF(H5=0,"",I5/H5) | N5: 2.1363458 | O5: 0.10585099 | P5: 0.022499283 | Q5: =IF(OR(O5="",P5=""),"",O5-P5) | R5: 339 | S5: 322.475 | T5: 1 | U5: 2 | V5: 110 | W5: 0 | X5: Retail only | Y5: =ROUND(100*(Scoring!$B$4*(1-IFERROR(PERCENTRANK($J$2:$J$46,J5),0.5))+Scoring!$B$5*IFERROR(PERCENTRANK($K$2:$K$46,K5),0.5)+Scoring!$B$6*IFERROR(PERCENTRANK($L$2:$L$46,L5),0.5)+Scoring!$B$7*IFERROR(PERCENTRANK($Q$2:$Q$46,Q5),0.5)+Scoring!$B$8*IFERROR(PERCENTRANK($N$2:$N$46,N5),0.5)+Scoring!$B$9*(1-IFERROR(PERCENTRANK($M$2:$M$46,M5),0.5))),0) | Z5: =IF(AND(Y5>=Scoring!$B$18,F5>=Scoring!$B$20,X5<>"Already takes broker loans"),"Tier 1",IF(Y5>=Scoring!$B$19,"Tier 2","Tier 3"))
A6: bank:34788 | B6: American Business Bank | C6: Los Angeles | D6: Los Angeles | E6: WWW.AMERICANBB.BANK | F6: 4417.375 | G6: 3938.208 | H6: 3124.695 | I6: 129.557 | J6: =IF(G6=0,"",H6/G6) | K6: 0.26868378 | L6: 0.1101037 | M6: =IF(H6=0,"",I6/H6) | N6: 1.7638141 | O6: 0.0170427 | P6: 0.079350544 | Q6: =IF(OR(O6="",P6=""),"",O6-P6) | X6: No HMDA mortgage reporting | Y6: =ROUND(100*(Scoring!$B$4*(1-IFERROR(PERCENTRANK($J$2:$J$46,J6),0.5))+Scoring!$B$5*IFERROR(PERCENTRANK($K$2:$K$46,K6),0.5)+Scoring!$B$6*IFERROR(PERCENTRANK($L$2:$L$46,L6),0.5)+Scoring!$B$7*IFERROR(PERCENTRANK($Q$2:$Q$46,Q6),0.5)+Scoring!$B$8*IFERROR(PERCENTRANK($N$2:$N$46,N6),0.5)+Scoring!$B$9*(1-IFERROR(PERCENTRANK($M$2:$M$46,M6),0.5))),0) | Z6: =IF(AND(Y6>=Scoring!$B$18,F6>=Scoring!$B$20,X6<>"Already takes broker loans"),"Tier 1",IF(Y6>=Scoring!$B$19,"Tier 2","Tier 3"))
A7: bank:58816 | B7: Royal Business Bank | C7: Los Angeles | D7: Los Angeles | E7: www.royalbusinessbankusa.com | F7: 4267.264 | G7: 3477.95 | H7: 3309.459 | I7: 1775.441 | J7: =IF(G7=0,"",H7/G7) | K7: 0.16276706 | L7: 0.1254492 | M7: =IF(H7=0,"",I7/H7) | N7: 2.3122035 | O7: 0.067696557 | P7: 0.023113153 | Q7: =IF(OR(O7="",P7=""),"",O7-P7) | R7: 607 | S7: 401.965 | T7: 0.93904448 | U7: 7 | V7: 70 | W7: 0.42833608 | X7: Already takes broker loans | Y7: =ROUND(100*(Scoring!$B$4*(1-IFERROR(PERCENTRANK($J$2:$J$46,J7),0.5))+Scoring!$B$5*IFERROR(PERCENTRANK($K$2:$K$46,K7),0.5)+Scoring!$B$6*IFERROR(PERCENTRANK($L$2:$L$46,L7),0.5)+Scoring!$B$7*IFERROR(PERCENTRANK($Q$2:$Q$46,Q7),0.5)+Scoring!$B$8*IFERROR(PERCENTRANK($N$2:$N$46,N7),0.5)+Scoring!$B$9*(1-IFERROR(PERCENTRANK($M$2:$M$46,M7),0.5))),0) | Z7: =IF(AND(Y7>=Scoring!$B$18,F7>=Scoring!$B$20,X7<>"Already takes broker loans"),"Tier 1",IF(Y7>=Scoring!$B$19,"Tier 2","Tier 3"))
A8: bank:57417 | B8: Commercial Bank of California | C8: Irvine | D8: Orange | E8: http://www.cbcal.com | F8: 3979.541 | G8: 3455.518 | H8: 2780.09 | I8: 97.685 | J8: =IF(G8=0,"",H8/G8) | K8: 0.27150217 | L8: 0.092734303 | M8: =IF(H8=0,"",I8/H8) | N8: 4.6996867 | O8: 0.13247625 | P8: 0.061884471 | Q8: =IF(OR(O8="",P8=""),"",O8-P8) | X8: No HMDA mortgage reporting | Y8: =ROUND(100*(Scoring!$B$4*(1-IFERROR(PERCENTRANK($J$2:$J$46,J8),0.5))+Scoring!$B$5*IFERROR(PERCENTRANK($K$2:$K$46,K8),0.5)+Scoring!$B$6*IFERROR(PERCENTRANK($L$2:$L$46,L8),0.5)+Scoring!$B$7*IFERROR(PERCENTRANK($Q$2:$Q$46,Q8),0.5)+Scoring!$B$8*IFERROR(PERCENTRANK($N$2:$N$46,N8),0.5)+Scoring!$B$9*(1-IFERROR(PERCENTRANK($M$2:$M$46,M8),0.5))),0) | Z8: =IF(AND(Y8>=Scoring!$B$18,F8>=Scoring!$B$20,X8<>"Already takes broker loans"),"Tier 1",IF(Y8>=Scoring!$B$19,"Tier 2","Tier 3"))
A9: bank:57463 | B9: PCB Bank | C9: Los Angeles | D9: Los Angeles | E9: www.mypcbbank.com | F9: 3469.065 | G9: 2933.655 | H9: 2934.956 | I9: 450.321 | J9: =IF(G9=0,"",H9/G9) | K9: 0.12957814 | L9: 0.11544222 | M9: =IF(H9=0,"",I9/H9) | N9: 3.0353608 | O9: 0.035753954 | P9: 0.046911618 | Q9: =IF(OR(O9="",P9=""),"",O9-P9) | R9: 120 | S9: 78.15 | T9: 1 | V9: 38 | X9: Unknown (small filer, channel not reported) | Y9: =ROUND(100*(Scoring!$B$4*(1-IFERROR(PERCENTRANK($J$2:$J$46,J9),0.5))+Scoring!$B$5*IFERROR(PERCENTRANK($K$2:$K$46,K9),0.5)+Scoring!$B$6*IFERROR(PERCENTRANK($L$2:$L$46,L9),0.5)+Scoring!$B$7*IFERROR(PERCENTRANK($Q$2:$Q$46,Q9),0.5)+Scoring!$B$8*IFERROR(PERCENTRANK($N$2:$N$46,N9),0.5)+Scoring!$B$9*(1-IFERROR(PERCENTRANK($M$2:$M$46,M9),0.5))),0) | Z9: =IF(AND(Y9>=Scoring!$B$18,F9>=Scoring!$B$20,X9<>"Already takes broker loans"),"Tier 1",IF(Y9>=Scoring!$B$19,"Tier 2","Tier 3"))
A10: bank:57944 | B10: Open Bank | C10: Los Angeles | D10: Los Angeles | E10: www.myopenbank.com | F10: 2745.961 | G10: 2369.409 | H10: 2280.366 | I10: 643.706 | J10: =IF(G10=0,"",H10/G10) | K10: 0.13891093 | L10: 0.10147272 | M10: =IF(H10=0,"",I10/H10) | N10: 2.5475621 | O10: 0.049818097 | P10: 0.090251655 | Q10: =IF(OR(O10="",P10=""),"",O10-P10) | R10: 18 | S10: 15.29 | T10: 1 | U10: 0 | V10: 2 | W10: 0.055555556 | X10: Mostly retail, a few broker loans | Y10: =ROUND(100*(Scoring!$B$4*(1-IFERROR(PERCENTRANK($J$2:$J$46,J10),0.5))+Scoring!$B$5*IFERROR(PERCENTRANK($K$2:$K$46,K10),0.5)+Scoring!$B$6*IFERROR(PERCENTRANK($L$2:$L$46,L10),0.5)+Scoring!$B$7*IFERROR(PERCENTRANK($Q$2:$Q$46,Q10),0.5)+Scoring!$B$8*IFERROR(PERCENTRANK($N$2:$N$46,N10),0.5)+Scoring!$B$9*(1-IFERROR(PERCENTRANK($M$2:$M$46,M10),0.5))),0) | Z10: =IF(AND(Y10>=Scoring!$B$18,F10>=Scoring!$B$20,X10<>"Already takes broker loans"),"Tier 1",IF(Y10>=Scoring!$B$19,"Tier 2","Tier 3"))
A11: bank:57873 | B11: Commonwealth Business Bank | C11: Los Angeles | D11: Los Angeles | E11: www.cbb-bank.com | F11: 1966.224 | G11: 1664.464 | H11: 1524.027 | I11: 98.659 | J11: =IF(G11=0,"",H11/G11) | K11: 0.20880988 | L11: 0.13932885 | M11: =IF(H11=0,"",I11/H11) | N11: 2.592328 | O11: 0.091110518 | P11: 0.042353406 | Q11: =IF(OR(O11="",P11=""),"",O11-P11) | X11: No HMDA mortgage reporting | Y11: =ROUND(100*(Scoring!$B$4*(1-IFERROR(PERCENTRANK($J$2:$J$46,J11),0.5))+Scoring!$B$5*IFERROR(PERCENTRANK($K$2:$K$46,K11),0.5)+Scoring!$B$6*IFERROR(PERCENTRANK($L$2:$L$46,L11),0.5)+Scoring!$B$7*IFERROR(PERCENTRANK($Q$2:$Q$46,Q11),0.5)+Scoring!$B$8*IFERROR(PERCENTRANK($N$2:$N$46,N11),0.5)+Scoring!$B$9*(1-IFERROR(PERCENTRANK($M$2:$M$46,M11),0.5))),0) | Z11: =IF(AND(Y11>=Scoring!$B$18,F11>=Scoring!$B$20,X11<>"Already takes broker loans"),"Tier 1",IF(Y11>=Scoring!$B$19,"Tier 2","Tier 3"))
A12: bank:58310 | B12: US Metro Bank | C12: Garden Grove | D12: Orange | E12: http://WWW.USMETROBANK.COM | F12: 1640.896 | G12: 1437.567 | H12: 1371.367 | I12: 195.945 | J12: =IF(G12=0,"",H12/G12) | K12: 0.14955427 | L12: 0.10416449 | M12: =IF(H12=0,"",I12/H12) | N12: 3.929876 | O12: 0.12227943 | P12: 0.11532515 | Q12: =IF(OR(O12="",P12=""),"",O12-P12) | X12: No HMDA mortgage reporting | Y12: =ROUND(100*(Scoring!$B$4*(1-IFERROR(PERCENTRANK($J$2:$J$46,J12),0.5))+Scoring!$B$5*IFERROR(PERCENTRANK($K$2:$K$46,K12),0.5)+Scoring!$B$6*IFERROR(PERCENTRANK($L$2:$L$46,L12),0.5)+Scoring!$B$7*IFERROR(PERCENTRANK($Q$2:$Q$46,Q12),0.5)+Scoring!$B$8*IFERROR(PERCENTRANK($N$2:$N$46,N12),0.5)+Scoring!$B$9*(1-IFERROR(PERCENTRANK($M$2:$M$46,M12),0.5))),0) | Z12: =IF(AND(Y12>=Scoring!$B$18,F12>=Scoring!$B$20,X12<>"Already takes broker loans"),"Tier 1",IF(Y12>=Scoring!$B$19,"Tier 2","Tier 3"))
A13: bank:32282 | B13: Malaga Bank F.S.B. | C13: Palos Verdes Peninsula | D13: Los Angeles | E13: www.malagabank.com | F13: 1448.853 | G13: 942.08 | H13: 1242.053 | I13: 78.919 | J13: =IF(G13=0,"",H13/G13) | K13: 0.12318848 | L13: 0.16759083 | M13: =IF(H13=0,"",I13/H13) | N13: 4.7280573 | O13: 0.015512742 | P13: 0.027197236 | Q13: =IF(OR(O13="",P13=""),"",O13-P13) | R13: 5 | S13: 4.175 | T13: 1 | V13: 5 | X13: Unknown (small filer, channel not reported) | Y13: =ROUND(100*(Scoring!$B$4*(1-IFERROR(PERCENTRANK($J$2:$J$46,J13),0.5))+Scoring!$B$5*IFERROR(PERCENTRANK($K$2:$K$46,K13),0.5)+Scoring!$B$6*IFERROR(PERCENTRANK($L$2:$L$46,L13),0.5)+Scoring!$B$7*IFERROR(PERCENTRANK($Q$2:$Q$46,Q13),0.5)+Scoring!$B$8*IFERROR(PERCENTRANK($N$2:$N$46,N13),0.5)+Scoring!$B$9*(1-IFERROR(PERCENTRANK($M$2:$M$46,M13),0.5))),0) | Z13: =IF(AND(Y13>=Scoring!$B$18,F13>=Scoring!$B$20,X13<>"Already takes broker loans"),"Tier 1",IF(Y13>=Scoring!$B$19,"Tier 2","Tier 3"))
A14: bank:23998 | B14: State Bank of India (California) | C14: Los Angeles | D14: Los Angeles | E14: www.sbical.com | F14: 1382.642 | G14: 1181.334 | H14: 1182.876 | I14: 0 | J14: =IF(G14=0,"",H14/G14) | K14: 0.13513983 | L14: 0.14048502 | M14: =IF(H14=0,"",I14/H14) | N14: 2.7561624 | O14: 0.059487626 | P14: 0.039424961 | Q14: =IF(OR(O14="",P14=""),"",O14-P14) | X14: No HMDA mortgage reporting | Y14: =ROUND(100*(Scoring!$B$4*(1-IFERROR(PERCENTRANK($J$2:$J$46,J14),0.5))+Scoring!$B$5*IFERROR(PERCENTRANK($K$2:$K$46,K14),0.5)+Scoring!$B$6*IFERROR(PERCENTRANK($L$2:$L$46,L14),0.5)+Scoring!$B$7*IFERROR(PERCENTRANK($Q$2:$Q$46,Q14),0.5)+Scoring!$B$8*IFERROR(PERCENTRANK($N$2:$N$46,N14),0.5)+Scoring!$B$9*(1-IFERROR(PERCENTRANK($M$2:$M$46,M14),0.5))),0) | Z14: =IF(AND(Y14>=Scoring!$B$18,F14>=Scoring!$B$20,X14<>"Already takes broker loans"),"Tier 1",IF(Y14>=Scoring!$B$19,"Tier 2","Tier 3"))
A15: bank:30879 | B15: Provident Savings Bank, F.S.B. | C15: Riverside | D15: Riverside | E15: www.myprovident.com | F15: 1208.112 | G15: 916.825 | H15: 1038.532 | I15: 573.27 | J15: =IF(G15=0,"",H15/G15) | K15: 0.11652479 | L15: 0.10295675 | M15: =IF(H15=0,"",I15/H15) | N15: 3.5398463 | O15: 0.024184071 | P15: -0.012960846 | Q15: =IF(OR(O15="",P15=""),"",O15-P15) | R15: 110 | S15: 93.43 | T15: 0.92727273 | U15: 0 | V15: 1 | W15: 0.98181818 | X15: Already takes broker loans | Y15: =ROUND(100*(Scoring!$B$4*(1-IFERROR(PERCENTRANK($J$2:$J$46,J15),0.5))+Scoring!$B$5*IFERROR(PERCENTRANK($K$2:$K$46,K15),0.5)+Scoring!$B$6*IFERROR(PERCENTRANK($L$2:$L$46,L15),0.5)+Scoring!$B$7*IFERROR(PERCENTRANK($Q$2:$Q$46,Q15),0.5)+Scoring!$B$8*IFERROR(PERCENTRANK($N$2:$N$46,N15),0.5)+Scoring!$B$9*(1-IFERROR(PERCENTRANK($M$2:$M$46,M15),0.5))),0) | Z15: =IF(AND(Y15>=Scoring!$B$18,F15>=Scoring!$B$20,X15<>"Already takes broker loans"),"Tier 1",IF(Y15>=Scoring!$B$19,"Tier 2","Tier 3"))
A16: bank:57176 | B16: Commerce West Bank | C16: Irvine | D16: Orange | E16: www.cwbk.com | F16: 1196.315 | G16: 1055.805 | H16: 779.651 | I16: 167.387 | J16: =IF(G16=0,"",H16/G16) | K16: 0.32811258 | L16: 0.11144714 | M16: =IF(H16=0,"",I16/H16) | N16: 2.0639533 | O16: 0.021381383 | P16: -0.038779196 | Q16: =IF(OR(O16="",P16=""),"",O16-P16) | X16: No HMDA mortgage reporting | Y16: =ROUND(100*(Scoring!$B$4*(1-IFERROR(PERCENTRANK($J$2:$J$46,J16),0.5))+Scoring!$B$5*IFERROR(PERCENTRANK($K$2:$K$46,K16),0.5)+Scoring!$B$6*IFERROR(PERCENTRANK($L$2:$L$46,L16),0.5)+Scoring!$B$7*IFERROR(PERCENTRANK($Q$2:$Q$46,Q16),0.5)+Scoring!$B$8*IFERROR(PERCENTRANK($N$2:$N$46,N16),0.5)+Scoring!$B$9*(1-IFERROR(PERCENTRANK($M$2:$M$46,M16),0.5))),0) | Z16: =IF(AND(Y16>=Scoring!$B$18,F16>=Scoring!$B$20,X16<>"Already takes broker loans"),"Tier 1",IF(Y16>=Scoring!$B$19,"Tier 2","Tier 3"))
A17: bank:58060 | B17: First General Bank | C17: Rowland Heights | D17: Los Angeles | E17: http://www.firstgeneralbank.com | F17: 1174.806 | G17: 837.772 | H17: 944.215 | I17: 34.645 | J17: =IF(G17=0,"",H17/G17) | K17: 0.17093205 | L17: 0.2629498 | M17: =IF(H17=0,"",I17/H17) | N17: 2.064006 | O17: 0.016675344 | P17: 0.015459649 | Q17: =IF(OR(O17="",P17=""),"",O17-P17) | X17: No HMDA mortgage reporting | Y17: =ROUND(100*(Scoring!$B$4*(1-IFERROR(PERCENTRANK($J$2:$J$46,J17),0.5))+Scoring!$B$5*IFERROR(PERCENTRANK($K$2:$K$46,K17),0.5)+Scoring!$B$6*IFERROR(PERCENTRANK($L$2:$L$46,L17),0.5)+Scoring!$B$7*IFERROR(PERCENTRANK($Q$2:$Q$46,Q17),0.5)+Scoring!$B$8*IFERROR(PERCENTRANK($N$2:$N$46,N17),0.5)+Scoring!$B$9*(1-IFERROR(PERCENTRANK($M$2:$M$46,M17),0.5))),0) | Z17: =IF(AND(Y17>=Scoring!$B$18,F17>=Scoring!$B$20,X17<>"Already takes broker loans"),"Tier 1",IF(Y17>=Scoring!$B$19,"Tier 2","Tier 3"))
A18: bank:34010 | B18: EverTrust Bank | C18: City Of Industry | D18: Los Angeles | E18: http://www.evertrustbank.com | F18: 1125.37 | G18: 848.571 | H18: 817.04 | I18: 88.018 | J18: =IF(G18=0,"",H18/G18) | K18: 0.19982939 | L18: 0.21707859 | M18: =IF(H18=0,"",I18/H18) | N18: 2.1096786 | O18: 0.15129787 | P18: 0.023730079 | Q18: =IF(OR(O18="",P18=""),"",O18-P18) | X18: No HMDA mortgage reporting | Y18: =ROUND(100*(Scoring!$B$4*(1-IFERROR(PERCENTRANK($J$2:$J$46,J18),0.5))+Scoring!$B$5*IFERROR(PERCENTRANK($K$2:$K$46,K18),0.5)+Scoring!$B$6*IFERROR(PERCENTRANK($L$2:$L$46,L18),0.5)+Scoring!$B$7*IFERROR(PERCENTRANK($Q$2:$Q$46,Q18),0.5)+Scoring!$B$8*IFERROR(PERCENTRANK($N$2:$N$46,N18),0.5)+Scoring!$B$9*(1-IFERROR(PERCENTRANK($M$2:$M$46,M18),0.5))),0) | Z18: =IF(AND(Y18>=Scoring!$B$18,F18>=Scoring!$B$20,X18<>"Already takes broker loans"),"Tier 1",IF(Y18>=Scoring!$B$19,"Tier 2","Tier 3"))
A19: bank:57585 | B19: Golden State Bank | C19: Glendale | D19: Los Angeles | E19: www.goldenstatebank.com | F19: 1000.102 | G19: 856.56 | H19: 858.061 | I19: 32.826 | J19: =IF(G19=0,"",H19/G19) | K19: 0.1323335 | L19: 0.11035294 | M19: =IF(H19=0,"",I19/H19) | N19: 4.2035583 | O19: 0.085793892 | P19: 0.092673243 | Q19: =IF(OR(O19="",P19=""),"",O19-P19) | X19: No HMDA mortgage reporting | Y19: =ROUND(100*(Scoring!$B$4*(1-IFERROR(PERCENTRANK($J$2:$J$46,J19),0.5))+Scoring!$B$5*IFERROR(PERCENTRANK($K$2:$K$46,K19),0.5)+Scoring!$B$6*IFERROR(PERCENTRANK($L$2:$L$46,L19),0.5)+Scoring!$B$7*IFERROR(PERCENTRANK($Q$2:$Q$46,Q19),0.5)+Scoring!$B$8*IFERROR(PERCENTRANK($N$2:$N$46,N19),0.5)+Scoring!$B$9*(1-IFERROR(PERCENTRANK($M$2:$M$46,M19),0.5))),0) | Z19: =IF(AND(Y19>=Scoring!$B$18,F19>=Scoring!$B$20,X19<>"Already takes broker loans"),"Tier 1",IF(Y19>=Scoring!$B$19,"Tier 2","Tier 3"))
A20: bank:21606 | B20: HCN Bank | C20: Riverside | D20: Riverside | E20: http://www.hcnbank.com | F20: 998.433 | G20: 846.287 | H20: 786.742 | I20: 1.203 | J20: =IF(G20=0,"",H20/G20) | K20: 0.19168036 | L20: 0.11704536 | M20: =IF(H20=0,"",I20/H20) | N20: 6.1106836 | O20: 0.0037479526 | P20: 0.08928564 | Q20: =IF(OR(O20="",P20=""),"",O20-P20) | X20: No HMDA mortgage reporting | Y20: =ROUND(100*(Scoring!$B$4*(1-IFERROR(PERCENTRANK($J$2:$J$46,J20),0.5))+Scoring!$B$5*IFERROR(PERCENTRANK($K$2:$K$46,K20),0.5)+Scoring!$B$6*IFERROR(PERCENTRANK($L$2:$L$46,L20),0.5)+Scoring!$B$7*IFERROR(PERCENTRANK($Q$2:$Q$46,Q20),0.5)+Scoring!$B$8*IFERROR(PERCENTRANK($N$2:$N$46,N20),0.5)+Scoring!$B$9*(1-IFERROR(PERCENTRANK($M$2:$M$46,M20),0.5))),0) | Z20: =IF(AND(Y20>=Scoring!$B$18,F20>=Scoring!$B$20,X20<>"Already takes broker loans"),"Tier 1",IF(Y20>=Scoring!$B$19,"Tier 2","Tier 3"))
A21: bank:58469 | B21: American Plus Bank, N.A. | C21: Arcadia | D21: Los Angeles | E21: www.bankaplus.com | F21: 935.046 | G21: 747.993 | H21: 804.179 | I21: 37.578 | J21: =IF(G21=0,"",H21/G21) | K21: 0.051047756 | L21: 0.16464303 | M21: =IF(H21=0,"",I21/H21) | N21: 4.5492027 | O21: 0.041981957 | P21: 0.046647439 | Q21: =IF(OR(O21="",P21=""),"",O21-P21) | X21: No HMDA mortgage reporting | Y21: =ROUND(100*(Scoring!$B$4*(1-IFERROR(PERCENTRANK($J$2:$J$46,J21),0.5))+Scoring!$B$5*IFERROR(PERCENTRANK($K$2:$K$46,K21),0.5)+Scoring!$B$6*IFERROR(PERCENTRANK($L$2:$L$46,L21),0.5)+Scoring!$B$7*IFERROR(PERCENTRANK($Q$2:$Q$46,Q21),0.5)+Scoring!$B$8*IFERROR(PERCENTRANK($N$2:$N$46,N21),0.5)+Scoring!$B$9*(1-IFERROR(PERCENTRANK($M$2:$M$46,M21),0.5))),0) | Z21: =IF(AND(Y21>=Scoring!$B$18,F21>=Scoring!$B$20,X21<>"Already takes broker loans"),"Tier 1",IF(Y21>=Scoring!$B$19,"Tier 2","Tier 3"))
A22: bank:34496 | B22: First Commercial Bank (USA) | C22: Alhambra | D22: Los Angeles | E22: bankfcb.com | F22: 849.866 | G22: 646.751 | H22: 732.112 | I22: 228.306 | J22: =IF(G22=0,"",H22/G22) | K22: 0.12530917 | L22: 0.23268476 | M22: =IF(H22=0,"",I22/H22) | N22: 1.625512 | O22: 0.042076125 | P22: 0.064315838 | Q22: =IF(OR(O22="",P22=""),"",O22-P22) | R22: 47 | S22: 33.125 | T22: 0.91489362 | V22: 13 | X22: Unknown (small filer, channel not reported) | Y22: =ROUND(100*(Scoring!$B$4*(1-IFERROR(PERCENTRANK($J$2:$J$46,J22),0.5))+Scoring!$B$5*IFERROR(PERCENTRANK($K$2:$K$46,K22),0.5)+Scoring!$B$6*IFERROR(PERCENTRANK($L$2:$L$46,L22),0.5)+Scoring!$B$7*IFERROR(PERCENTRANK($Q$2:$Q$46,Q22),0.5)+Scoring!$B$8*IFERROR(PERCENTRANK($N$2:$N$46,N22),0.5)+Scoring!$B$9*(1-IFERROR(PERCENTRANK($M$2:$M$46,M22),0.5))),0) | Z22: =IF(AND(Y22>=Scoring!$B$18,F22>=Scoring!$B$20,X22<>"Already takes broker loans"),"Tier 1",IF(Y22>=Scoring!$B$19,"Tier 2","Tier 3"))
A23: bank:57101 | B23: Mission Valley Bank | C23: Sun Valley | D23: Los Angeles | E23: www.missionvalleybank.com | F23: 782.004 | G23: 615.31 | H23: 630.507 | I23: 10.562 | J23: =IF(G23=0,"",H23/G23) | K23: 0.14292638 | L23: 0.10995416 | M23: =IF(H23=0,"",I23/H23) | N23: 2.2548803 | O23: 0.026258994 | P23: 0.057276767 | Q23: =IF(OR(O23="",P23=""),"",O23-P23) | X23: No HMDA mortgage reporting | Y23: =ROUND(100*(Scoring!$B$4*(1-IFERROR(PERCENTRANK($J$2:$J$46,J23),0.5))+Scoring!$B$5*IFERROR(PERCENTRANK($K$2:$K$46,K23),0.5)+Scoring!$B$6*IFERROR(PERCENTRANK($L$2:$L$46,L23),0.5)+Scoring!$B$7*IFERROR(PERCENTRANK($Q$2:$Q$46,Q23),0.5)+Scoring!$B$8*IFERROR(PERCENTRANK($N$2:$N$46,N23),0.5)+Scoring!$B$9*(1-IFERROR(PERCENTRANK($M$2:$M$46,M23),0.5))),0) | Z23: =IF(AND(Y23>=Scoring!$B$18,F23>=Scoring!$B$20,X23<>"Already takes broker loans"),"Tier 1",IF(Y23>=Scoring!$B$19,"Tier 2","Tier 3"))
A24: bank:22366 | B24: GBC International Bank | C24: Los Angeles | D24: Los Angeles | E24: http://www.gbcib.com | F24: 658.463 | G24: 504.604 | H24: 456.915 | I24: 2.133 | J24: =IF(G24=0,"",H24/G24) | K24: 0.28676934 | L24: 0.15943555 | M24: =IF(H24=0,"",I24/H24) | N24: 2.6863223 | O24: -0.015892642 | P24: 0.023759217 | Q24: =IF(OR(O24="",P24=""),"",O24-P24) | X24: No HMDA mortgage reporting | Y24: =ROUND(100*(Scoring!$B$4*(1-IFERROR(PERCENTRANK($J$2:$J$46,J24),0.5))+Scoring!$B$5*IFERROR(PERCENTRANK($K$2:$K$46,K24),0.5)+Scoring!$B$6*IFERROR(PERCENTRANK($L$2:$L$46,L24),0.5)+Scoring!$B$7*IFERROR(PERCENTRANK($Q$2:$Q$46,Q24),0.5)+Scoring!$B$8*IFERROR(PERCENTRANK($N$2:$N$46,N24),0.5)+Scoring!$B$9*(1-IFERROR(PERCENTRANK($M$2:$M$46,M24),0.5))),0) | Z24: =IF(AND(Y24>=Scoring!$B$18,F24>=Scoring!$B$20,X24<>"Already takes broker loans"),"Tier 1",IF(Y24>=Scoring!$B$19,"Tier 2","Tier 3"))
A25: bank:58588 | B25: Partners Bank of California | C25: Mission Viejo | D25: Orange | E25: www.partnersbankca.com | F25: 602.153 | G25: 508.991 | H25: 505.82 | I25: 64.001 | J25: =IF(G25=0,"",H25/G25) | K25: 0.15813755 | L25: 0.1167327 | M25: =IF(H25=0,"",I25/H25) | N25: 3.6500739 | O25: -0.11906505 | P25: 0.20725662 | Q25: =IF(OR(O25="",P25=""),"",O25-P25) | X25: No HMDA mortgage reporting | Y25: =ROUND(100*(Scoring!$B$4*(1-IFERROR(PERCENTRANK($J$2:$J$46,J25),0.5))+Scoring!$B$5*IFERROR(PERCENTRANK($K$2:$K$46,K25),0.5)+Scoring!$B$6*IFERROR(PERCENTRANK($L$2:$L$46,L25),0.5)+Scoring!$B$7*IFERROR(PERCENTRANK($Q$2:$Q$46,Q25),0.5)+Scoring!$B$8*IFERROR(PERCENTRANK($N$2:$N$46,N25),0.5)+Scoring!$B$9*(1-IFERROR(PERCENTRANK($M$2:$M$46,M25),0.5))),0) | Z25: =IF(AND(Y25>=Scoring!$B$18,F25>=Scoring!$B$20,X25<>"Already takes broker loans"),"Tier 1",IF(Y25>=Scoring!$B$19,"Tier 2","Tier 3"))
A26: bank:23086 | B26: New OMNI Bank, National Association | C26: Alhambra | D26: Los Angeles | E26: WWW.NEWOMNIBANK.COM | F26: 517.936 | G26: 373.759 | H26: 384.558 | I26: 165.411 | J26: =IF(G26=0,"",H26/G26) | K26: 0.21833393 | L26: 0.27114538 | M26: =IF(H26=0,"",I26/H26) | N26: 1.2977626 | O26: -2.4079108e-05 | P26: 0.077151036 | Q26: =IF(OR(O26="",P26=""),"",O26-P26) | X26: No HMDA mortgage reporting | Y26: =ROUND(100*(Scoring!$B$4*(1-IFERROR(PERCENTRANK($J$2:$J$46,J26),0.5))+Scoring!$B$5*IFERROR(PERCENTRANK($K$2:$K$46,K26),0.5)+Scoring!$B$6*IFERROR(PERCENTRANK($L$2:$L$46,L26),0.5)+Scoring!$B$7*IFERROR(PERCENTRANK($Q$2:$Q$46,Q26),0.5)+Scoring!$B$8*IFERROR(PERCENTRANK($N$2:$N$46,N26),0.5)+Scoring!$B$9*(1-IFERROR(PERCENTRANK($M$2:$M$46,M26),0.5))),0) | Z26: =IF(AND(Y26>=Scoring!$B$18,F26>=Scoring!$B$20,X26<>"Already takes broker loans"),"Tier 1",IF(Y26>=Scoring!$B$19,"Tier 2","Tier 3"))
A27: bank:35366 | B27: Chino Commercial Bank, N.A. | C27: Chino | D27: San Bernardino | E27: www.chinocommercialbank.com | F27: 516.688 | G27: 397.231 | H27: 239.264 | I27: 18.446 | J27: =IF(G27=0,"",H27/G27) | K27: 0.4973814 | L27: 0.12510506 | M27: =IF(H27=0,"",I27/H27) | N27: 2.1297831 | O27: 0.048664588 | P27: 0.16290395 | Q27: =IF(OR(O27="",P27=""),"",O27-P27) | X27: No HMDA mortgage reporting | Y27: =ROUND(100*(Scoring!$B$4*(1-IFERROR(PERCENTRANK($J$2:$J$46,J27),0.5))+Scoring!$B$5*IFERROR(PERCENTRANK($K$2:$K$46,K27),0.5)+Scoring!$B$6*IFERROR(PERCENTRANK($L$2:$L$46,L27),0.5)+Scoring!$B$7*IFERROR(PERCENTRANK($Q$2:$Q$46,Q27),0.5)+Scoring!$B$8*IFERROR(PERCENTRANK($N$2:$N$46,N27),0.5)+Scoring!$B$9*(1-IFERROR(PERCENTRANK($M$2:$M$46,M27),0.5))),0) | Z27: =IF(AND(Y27>=Scoring!$B$18,F27>=Scoring!$B$20,X27<>"Already takes broker loans"),"Tier 1",IF(Y27>=Scoring!$B$19,"Tier 2","Tier 3"))
A28: bank:24332 | B28: First Credit Bank | C28: Los Angeles | D28: Los Angeles | F28: 515.839 | G28: 265.294 | H28: 408.96 | I28: 40.919 | J28: =IF(G28=0,"",H28/G28) | K28: 0.13735681 | L28: 0.47614441 | M28: =IF(H28=0,"",I28/H28) | N28: 1.101237 | O28: -0.060423934 | P28: -0.047690015 | Q28: =IF(OR(O28="",P28=""),"",O28-P28) | X28: No HMDA mortgage reporting | Y28: =ROUND(100*(Scoring!$B$4*(1-IFERROR(PERCENTRANK($J$2:$J$46,J28),0.5))+Scoring!$B$5*IFERROR(PERCENTRANK($K$2:$K$46,K28),0.5)+Scoring!$B$6*IFERROR(PERCENTRANK($L$2:$L$46,L28),0.5)+Scoring!$B$7*IFERROR(PERCENTRANK($Q$2:$Q$46,Q28),0.5)+Scoring!$B$8*IFERROR(PERCENTRANK($N$2:$N$46,N28),0.5)+Scoring!$B$9*(1-IFERROR(PERCENTRANK($M$2:$M$46,M28),0.5))),0) | Z28: =IF(AND(Y28>=Scoring!$B$18,F28>=Scoring!$B$20,X28<>"Already takes broker loans"),"Tier 1",IF(Y28>=Scoring!$B$19,"Tier 2","Tier 3"))
A29: bank:58218 | B29: First Pacific Bank | C29: Whittier | D29: Los Angeles | E29: www.firstpacbank.com | F29: 514.36 | G29: 420.102 | H29: 352.887 | I29: 86.647 | J29: =IF(G29=0,"",H29/G29) | K29: 0.19979975 | L29: 0.092481904 | M29: =IF(H29=0,"",I29/H29) | N29: 2.4319579 | O29: 0.11084904 | P29: 0.13145061 | Q29: =IF(OR(O29="",P29=""),"",O29-P29) | X29: No HMDA mortgage reporting | Y29: =ROUND(100*(Scoring!$B$4*(1-IFERROR(PERCENTRANK($J$2:$J$46,J29),0.5))+Scoring!$B$5*IFERROR(PERCENTRANK($K$2:$K$46,K29),0.5)+Scoring!$B$6*IFERROR(PERCENTRANK($L$2:$L$46,L29),0.5)+Scoring!$B$7*IFERROR(PERCENTRANK($Q$2:$Q$46,Q29),0.5)+Scoring!$B$8*IFERROR(PERCENTRANK($N$2:$N$46,N29),0.5)+Scoring!$B$9*(1-IFERROR(PERCENTRANK($M$2:$M$46,M29),0.5))),0) | Z29: =IF(AND(Y29>=Scoring!$B$18,F29>=Scoring!$B$20,X29<>"Already takes broker loans"),"Tier 1",IF(Y29>=Scoring!$B$19,"Tier 2","Tier 3"))
A30: bank:58401 | B30: Mega Bank | C30: San Gabriel | D30: Los Angeles | E30: https://www.megabankusa.com | F30: 506.664 | G30: 426.08 | H30: 433.1 | I30: 23.392 | J30: =IF(G30=0,"",H30/G30) | K30: 0.10523147 | L30: 0.14433342 | M30: =IF(H30=0,"",I30/H30) | N30: 3.7250416 | O30: -0.019554602 | P30: 0.049234817 | Q30: =IF(OR(O30="",P30=""),"",O30-P30) | X30: No HMDA mortgage reporting | Y30: =ROUND(100*(Scoring!$B$4*(1-IFERROR(PERCENTRANK($J$2:$J$46,J30),0.5))+Scoring!$B$5*IFERROR(PERCENTRANK($K$2:$K$46,K30),0.5)+Scoring!$B$6*IFERROR(PERCENTRANK($L$2:$L$46,L30),0.5)+Scoring!$B$7*IFERROR(PERCENTRANK($Q$2:$Q$46,Q30),0.5)+Scoring!$B$8*IFERROR(PERCENTRANK($N$2:$N$46,N30),0.5)+Scoring!$B$9*(1-IFERROR(PERCENTRANK($M$2:$M$46,M30),0.5))),0) | Z30: =IF(AND(Y30>=Scoring!$B$18,F30>=Scoring!$B$20,X30<>"Already takes broker loans"),"Tier 1",IF(Y30>=Scoring!$B$19,"Tier 2","Tier 3"))
A31: bank:58234 | B31: Pacific Alliance Bank | C31: San Gabriel | D31: Los Angeles | E31: www.pacificalliancebank.com | F31: 454.372 | G31: 369.168 | H31: 347.994 | I31: 44.68 | J31: =IF(G31=0,"",H31/G31) | K31: 0.1800199 | L31: 0.13370668 | M31: =IF(H31=0,"",I31/H31) | N31: 4.0690387 | O31: 0.060681285 | P31: 0.002879004 | Q31: =IF(OR(O31="",P31=""),"",O31-P31) | X31: No HMDA mortgage reporting | Y31: =ROUND(100*(Scoring!$B$4*(1-IFERROR(PERCENTRANK($J$2:$J$46,J31),0.5))+Scoring!$B$5*IFERROR(PERCENTRANK($K$2:$K$46,K31),0.5)+Scoring!$B$6*IFERROR(PERCENTRANK($L$2:$L$46,L31),0.5)+Scoring!$B$7*IFERROR(PERCENTRANK($Q$2:$Q$46,Q31),0.5)+Scoring!$B$8*IFERROR(PERCENTRANK($N$2:$N$46,N31),0.5)+Scoring!$B$9*(1-IFERROR(PERCENTRANK($M$2:$M$46,M31),0.5))),0) | Z31: =IF(AND(Y31>=Scoring!$B$18,F31>=Scoring!$B$20,X31<>"Already takes broker loans"),"Tier 1",IF(Y31>=Scoring!$B$19,"Tier 2","Tier 3"))
A32: bank:26363 | B32: Community Commerce Bank | C32: Claremont | D32: Los Angeles | E32: www.ccombank.com | F32: 422.736 | G32: 317.509 | H32: 317.747 | I32: 11.126 | J32: =IF(G32=0,"",H32/G32) | K32: 0.14999196 | L32: 0.15253258 | M32: =IF(H32=0,"",I32/H32) | N32: 2.2491112 | O32: 0.063760143 | P32: 0.081169273 | Q32: =IF(OR(O32="",P32=""),"",O32-P32) | X32: No HMDA mortgage reporting | Y32: =ROUND(100*(Scoring!$B$4*(1-IFERROR(PERCENTRANK($J$2:$J$46,J32),0.5))+Scoring!$B$5*IFERROR(PERCENTRANK($K$2:$K$46,K32),0.5)+Scoring!$B$6*IFERROR(PERCENTRANK($L$2:$L$46,L32),0.5)+Scoring!$B$7*IFERROR(PERCENTRANK($Q$2:$Q$46,Q32),0.5)+Scoring!$B$8*IFERROR(PERCENTRANK($N$2:$N$46,N32),0.5)+Scoring!$B$9*(1-IFERROR(PERCENTRANK($M$2:$M$46,M32),0.5))),0) | Z32: =IF(AND(Y32>=Scoring!$B$18,F32>=Scoring!$B$20,X32<>"Already takes broker loans"),"Tier 1",IF(Y32>=Scoring!$B$19,"Tier 2","Tier 3"))
A33: bank:35331 | B33: Liberty Bank, National Association | C33: Irvine | D33: Orange | E33: www.libertybk.com | F33: 399.182 | G33: 336.266 | H33: 329.379 | I33: 22.579 | J33: =IF(G33=0,"",H33/G33) | K33: 0.15291521 | L33: 0.14442363 | M33: =IF(H33=0,"",I33/H33) | N33: 4.8011194 | O33: 0.026330809 | P33: -0.12647553 | Q33: =IF(OR(O33="",P33=""),"",O33-P33) | X33: No HMDA mortgage reporting | Y33: =ROUND(100*(Scoring!$B$4*(1-IFERROR(PERCENTRANK($J$2:$J$46,J33),0.5))+Scoring!$B$5*IFERROR(PERCENTRANK($K$2:$K$46,K33),0.5)+Scoring!$B$6*IFERROR(PERCENTRANK($L$2:$L$46,L33),0.5)+Scoring!$B$7*IFERROR(PERCENTRANK($Q$2:$Q$46,Q33),0.5)+Scoring!$B$8*IFERROR(PERCENTRANK($N$2:$N$46,N33),0.5)+Scoring!$B$9*(1-IFERROR(PERCENTRANK($M$2:$M$46,M33),0.5))),0) | Z33: =IF(AND(Y33>=Scoring!$B$18,F33>=Scoring!$B$20,X33<>"Already takes broker loans"),"Tier 1",IF(Y33>=Scoring!$B$19,"Tier 2","Tier 3"))
A34: bank:30722 | B34: Universal Bank | C34: West Covina | D34: Los Angeles | E34: https://www.universalbank.com | F34: 388.009 | G34: 275.101 | H34: 261.579 | I34: 8.969 | J34: =IF(G34=0,"",H34/G34) | K34: 0.26760977 | L34: 0.17801088 | M34: =IF(H34=0,"",I34/H34) | N34: 3.4724771 | O34: 0.033825629 | P34: -0.067241724 | Q34: =IF(OR(O34="",P34=""),"",O34-P34) | X34: No HMDA mortgage reporting | Y34: =ROUND(100*(Scoring!$B$4*(1-IFERROR(PERCENTRANK($J$2:$J$46,J34),0.5))+Scoring!$B$5*IFERROR(PERCENTRANK($K$2:$K$46,K34),0.5)+Scoring!$B$6*IFERROR(PERCENTRANK($L$2:$L$46,L34),0.5)+Scoring!$B$7*IFERROR(PERCENTRANK($Q$2:$Q$46,Q34),0.5)+Scoring!$B$8*IFERROR(PERCENTRANK($N$2:$N$46,N34),0.5)+Scoring!$B$9*(1-IFERROR(PERCENTRANK($M$2:$M$46,M34),0.5))),0) | Z34: =IF(AND(Y34>=Scoring!$B$18,F34>=Scoring!$B$20,X34<>"Already takes broker loans"),"Tier 1",IF(Y34>=Scoring!$B$19,"Tier 2","Tier 3"))
A35: bank:57444 | B35: American Continental Bank | C35: City Of Industry | D35: Los Angeles | E35: http://www.americancontinentalbank.com | F35: 385.265 | G35: 316.728 | H35: 287.221 | I35: 114.266 | J35: =IF(G35=0,"",H35/G35) | K35: 0.22694509 | L35: 0.16233157 | M35: =IF(H35=0,"",I35/H35) | N35: 1.9563891 | O35: 0.072149593 | P35: 0.013100206 | Q35: =IF(OR(O35="",P35=""),"",O35-P35) | R35: 42 | S35: 47.29 | T35: 1 | V35: 21 | X35: Unknown (small filer, channel not reported) | Y35: =ROUND(100*(Scoring!$B$4*(1-IFERROR(PERCENTRANK($J$2:$J$46,J35),0.5))+Scoring!$B$5*IFERROR(PERCENTRANK($K$2:$K$46,K35),0.5)+Scoring!$B$6*IFERROR(PERCENTRANK($L$2:$L$46,L35),0.5)+Scoring!$B$7*IFERROR(PERCENTRANK($Q$2:$Q$46,Q35),0.5)+Scoring!$B$8*IFERROR(PERCENTRANK($N$2:$N$46,N35),0.5)+Scoring!$B$9*(1-IFERROR(PERCENTRANK($M$2:$M$46,M35),0.5))),0) | Z35: =IF(AND(Y35>=Scoring!$B$18,F35>=Scoring!$B$20,X35<>"Already takes broker loans"),"Tier 1",IF(Y35>=Scoring!$B$19,"Tier 2","Tier 3"))
A36: bank:59098 | B36: Infinity Bank | C36: Santa Ana | D36: Orange | E36: www.infinity.bank | F36: 359.51 | G36: 310.467 | H36: 255.149 | I36: 54.112 | J36: =IF(G36=0,"",H36/G36) | K36: 0.28521877 | L36: 0.13031808 | M36: =IF(H36=0,"",I36/H36) | N36: 1.1329208 | O36: 0.064621325 | P36: 0.15268441 | Q36: =IF(OR(O36="",P36=""),"",O36-P36) | X36: No HMDA mortgage reporting | Y36: =ROUND(100*(Scoring!$B$4*(1-IFERROR(PERCENTRANK($J$2:$J$46,J36),0.5))+Scoring!$B$5*IFERROR(PERCENTRANK($K$2:$K$46,K36),0.5)+Scoring!$B$6*IFERROR(PERCENTRANK($L$2:$L$46,L36),0.5)+Scoring!$B$7*IFERROR(PERCENTRANK($Q$2:$Q$46,Q36),0.5)+Scoring!$B$8*IFERROR(PERCENTRANK($N$2:$N$46,N36),0.5)+Scoring!$B$9*(1-IFERROR(PERCENTRANK($M$2:$M$46,M36),0.5))),0) | Z36: =IF(AND(Y36>=Scoring!$B$18,F36>=Scoring!$B$20,X36<>"Already takes broker loans"),"Tier 1",IF(Y36>=Scoring!$B$19,"Tier 2","Tier 3"))
A37: bank:59245 | B37: Genesis Bank | C37: Newport Beach | D37: Orange | E37: www.mygenesisbank.com | F37: 340.254 | G37: 292.418 | H37: 260.819 | I37: 12.279 | J37: =IF(G37=0,"",H37/G37) | K37: 0.19721149 | L37: 0.11012386 | M37: =IF(H37=0,"",I37/H37) | N37: 4.4157387 | O37: -0.31935506 | P37: -0.13564254 | Q37: =IF(OR(O37="",P37=""),"",O37-P37) | X37: No HMDA mortgage reporting | Y37: =ROUND(100*(Scoring!$B$4*(1-IFERROR(PERCENTRANK($J$2:$J$46,J37),0.5))+Scoring!$B$5*IFERROR(PERCENTRANK($K$2:$K$46,K37),0.5)+Scoring!$B$6*IFERROR(PERCENTRANK($L$2:$L$46,L37),0.5)+Scoring!$B$7*IFERROR(PERCENTRANK($Q$2:$Q$46,Q37),0.5)+Scoring!$B$8*IFERROR(PERCENTRANK($N$2:$N$46,N37),0.5)+Scoring!$B$9*(1-IFERROR(PERCENTRANK($M$2:$M$46,M37),0.5))),0) | Z37: =IF(AND(Y37>=Scoring!$B$18,F37>=Scoring!$B$20,X37<>"Already takes broker loans"),"Tier 1",IF(Y37>=Scoring!$B$19,"Tier 2","Tier 3"))
A38: bank:59296 | B38: Bank Irvine | C38: Irvine | D38: Orange | E38: www.bankirvine.com | F38: 305.639 | G38: 234.749 | H38: 238.563 | I38: 144.099 | J38: =IF(G38=0,"",H38/G38) | K38: 0.21738718 | L38: 0.22762777 | M38: =IF(H38=0,"",I38/H38) | N38: 0.81365145 | O38: 0.4293656 | P38: 0.26441905 | Q38: =IF(OR(O38="",P38=""),"",O38-P38) | X38: No HMDA mortgage reporting | Y38: =ROUND(100*(Scoring!$B$4*(1-IFERROR(PERCENTRANK($J$2:$J$46,J38),0.5))+Scoring!$B$5*IFERROR(PERCENTRANK($K$2:$K$46,K38),0.5)+Scoring!$B$6*IFERROR(PERCENTRANK($L$2:$L$46,L38),0.5)+Scoring!$B$7*IFERROR(PERCENTRANK($Q$2:$Q$46,Q38),0.5)+Scoring!$B$8*IFERROR(PERCENTRANK($N$2:$N$46,N38),0.5)+Scoring!$B$9*(1-IFERROR(PERCENTRANK($M$2:$M$46,M38),0.5))),0) | Z38: =IF(AND(Y38>=Scoring!$B$18,F38>=Scoring!$B$20,X38<>"Already takes broker loans"),"Tier 1",IF(Y38>=Scoring!$B$19,"Tier 2","Tier 3"))
A39: bank:23805 | B39: United Pacific Bank | C39: City Of Industry | D39: Los Angeles | E39: www.upbnet.com | F39: 191.036 | G39: 156.802 | H39: 154.49 | I39: 0.018 | J39: =IF(G39=0,"",H39/G39) | K39: 0.18208086 | L39: 0.17394254 | M39: =IF(H39=0,"",I39/H39) | N39: 3.745342 | O39: 0.099624113 | P39: 0.18621293 | Q39: =IF(OR(O39="",P39=""),"",O39-P39) | X39: No HMDA mortgage reporting | Y39: =ROUND(100*(Scoring!$B$4*(1-IFERROR(PERCENTRANK($J$2:$J$46,J39),0.5))+Scoring!$B$5*IFERROR(PERCENTRANK($K$2:$K$46,K39),0.5)+Scoring!$B$6*IFERROR(PERCENTRANK($L$2:$L$46,L39),0.5)+Scoring!$B$7*IFERROR(PERCENTRANK($Q$2:$Q$46,Q39),0.5)+Scoring!$B$8*IFERROR(PERCENTRANK($N$2:$N$46,N39),0.5)+Scoring!$B$9*(1-IFERROR(PERCENTRANK($M$2:$M$46,M39),0.5))),0) | Z39: =IF(AND(Y39>=Scoring!$B$18,F39>=Scoring!$B$20,X39<>"Already takes broker loans"),"Tier 1",IF(Y39>=Scoring!$B$19,"Tier 2","Tier 3"))
A40: bank:59290 | B40: Beach Cities Commercial Bank | C40: Irvine | D40: Orange | E40: www.beachcitiescb.com | F40: 188.867 | G40: 139.556 | H40: 153.508 | I40: 17.493 | J40: =IF(G40=0,"",H40/G40) | K40: 0.17608158 | L40: 0.098080575 | M40: =IF(H40=0,"",I40/H40) | N40: 2.733293 | O40: 0.048985636 | P40: 0.16881891 | Q40: =IF(OR(O40="",P40=""),"",O40-P40) | X40: No HMDA mortgage reporting | Y40: =ROUND(100*(Scoring!$B$4*(1-IFERROR(PERCENTRANK($J$2:$J$46,J40),0.5))+Scoring!$B$5*IFERROR(PERCENTRANK($K$2:$K$46,K40),0.5)+Scoring!$B$6*IFERROR(PERCENTRANK($L$2:$L$46,L40),0.5)+Scoring!$B$7*IFERROR(PERCENTRANK($Q$2:$Q$46,Q40),0.5)+Scoring!$B$8*IFERROR(PERCENTRANK($N$2:$N$46,N40),0.5)+Scoring!$B$9*(1-IFERROR(PERCENTRANK($M$2:$M$46,M40),0.5))),0) | Z40: =IF(AND(Y40>=Scoring!$B$18,F40>=Scoring!$B$20,X40<>"Already takes broker loans"),"Tier 1",IF(Y40>=Scoring!$B$19,"Tier 2","Tier 3"))
...

Sheet Credit Unions
A1: Key | B1: Institution | C1: City | D1: County | E1: Total assets ($M) | F1: Shares/deposits ($M) | G1: Total loans ($M) | H1: 1st-lien 1-4 family loans ($M) | I1: Loan-to-share | J1: Liquidity (cash+inv / assets) | K1: Net worth ratio | L1: 1st mtg % of loans | M1: 1st mtg originated YTD ($M) | N1: Annualized originations / assets | O1: 1st mtg sold YTD ($M) | P1: Share growth YoY | Q1: Loan growth YoY | R1: Funding gap (share g - loan g) | S1: HMDA 2025 originations (#) | T1: HMDA 2025 volume ($M) | U1: % kept in portfolio | V1: Non-QM-feature loans (IO/balloon/non-amort.) | W1: Investor / business-purpose loans | X1: Broker-channel share | Y1: Wholesale status | Z1: Capacity score | AA1: Tier | AB1: CEO / contact (fill in) | AC1: Notes (fill in)
A2: cu:1999 | B2: Logix CU | C2: Valencia | D2: Los Angeles | E2: 9687.8049 | F2: 8130.6756 | G2: 7759.7516 | H2: 3850.703 | I2: =IF(F2=0,"",G2/F2) | J2: 0.17708249 | K2: 0.1567 | L2: =IF(G2=0,"",H2/G2) | M2: 181.59677 | N2: =IF(E2=0,"",2*M2/E2) | O2: 17.745831 | P2: 0.035645613 | Q2: 0.0093343985 | R2: =IF(OR(P2="",Q2=""),"",P2-Q2) | S2: 900 | T2: 304.05 | U2: 0.9 | V2: 44 | W2: 65 | X2: 0 | Y2: Retail only | Z2: =ROUND(100*(Scoring!$B$11*(1-IFERROR(PERCENTRANK($I$2:$I$67,I2),0.5))+Scoring!$B$12*IFERROR(PERCENTRANK($J$2:$J$67,J2),0.5)+Scoring!$B$13*IFERROR(PERCENTRANK($K$2:$K$67,K2),0.5)+Scoring!$B$14*IFERROR(PERCENTRANK($R$2:$R$67,R2),0.5)+Scoring!$B$15*(1-IFERROR(PERCENTRANK($N$2:$N$67,N2),0.5))+Scoring!$B$16*(1-IFERROR(PERCENTRANK($L$2:$L$67,L2),0.5))),0) | AA2: =IF(AND(Z2>=Scoring!$B$18,E2>=Scoring!$B$20,Y2<>"Already takes broker loans"),"Tier 1",IF(Z2>=Scoring!$B$19,"Tier 2","Tier 3"))
